[2022-06-27 07:06:00,485] {taskinstance.py:1043} INFO - Dependencies all met for <TaskInstance: first_airflow_dag.process_datetime scheduled__2022-06-27T07:05:00+00:00 [queued]>
[2022-06-27 07:06:00,494] {taskinstance.py:1043} INFO - Dependencies all met for <TaskInstance: first_airflow_dag.process_datetime scheduled__2022-06-27T07:05:00+00:00 [queued]>
[2022-06-27 07:06:00,495] {taskinstance.py:1249} INFO - 
--------------------------------------------------------------------------------
[2022-06-27 07:06:00,495] {taskinstance.py:1250} INFO - Starting attempt 1 of 1
[2022-06-27 07:06:00,495] {taskinstance.py:1251} INFO - 
--------------------------------------------------------------------------------
[2022-06-27 07:06:00,503] {taskinstance.py:1270} INFO - Executing <Task(PythonOperator): process_datetime> on 2022-06-27 07:05:00+00:00
[2022-06-27 07:06:00,509] {standard_task_runner.py:52} INFO - Started process 946 to run task
[2022-06-27 07:06:00,511] {standard_task_runner.py:79} INFO - Running: ['***', 'tasks', 'run', 'first_***_dag', 'process_datetime', 'scheduled__2022-06-27T07:05:00+00:00', '--job-id', '60', '--raw', '--subdir', 'DAGS_FOLDER/second_demo.py', '--cfg-path', '/tmp/tmpjdg6_njx', '--error-file', '/tmp/tmps9on14vw']
[2022-06-27 07:06:00,512] {standard_task_runner.py:80} INFO - Job 60: Subtask process_datetime
[2022-06-27 07:06:00,566] {logging_mixin.py:109} INFO - Running <TaskInstance: first_***_dag.process_datetime scheduled__2022-06-27T07:05:00+00:00 [running]> on host f32f6d4577d5
[2022-06-27 07:06:00,611] {taskinstance.py:1448} INFO - Exporting the following env vars:
AIRFLOW_CTX_DAG_OWNER=***
AIRFLOW_CTX_DAG_ID=first_***_dag
AIRFLOW_CTX_TASK_ID=process_datetime
AIRFLOW_CTX_EXECUTION_DATE=2022-06-27T07:05:00+00:00
AIRFLOW_CTX_DAG_RUN_ID=scheduled__2022-06-27T07:05:00+00:00
[2022-06-27 07:06:00,617] {taskinstance.py:1774} ERROR - Task failed with exception
Traceback (most recent call last):
  File "/home/airflow/.local/lib/python3.7/site-packages/airflow/operators/python.py", line 174, in execute
    return_value = self.execute_callable()
  File "/home/airflow/.local/lib/python3.7/site-packages/airflow/operators/python.py", line 188, in execute_callable
    return self.python_callable(*self.op_args, **self.op_kwargs)
  File "/opt/airflow/dags/second_demo.py", line 17, in process_datetime
    'year': int(dt[-1]),
ValueError: invalid literal for int() with base 10: 'None'
[2022-06-27 07:06:00,626] {taskinstance.py:1288} INFO - Marking task as FAILED. dag_id=first_***_dag, task_id=process_datetime, execution_date=20220627T070500, start_date=20220627T070600, end_date=20220627T070600
[2022-06-27 07:06:00,637] {standard_task_runner.py:98} ERROR - Failed to execute job 60 for task process_datetime (invalid literal for int() with base 10: 'None'; 946)
[2022-06-27 07:06:00,683] {local_task_job.py:154} INFO - Task exited with return code 1
[2022-06-27 07:06:00,706] {local_task_job.py:264} INFO - 0 downstream tasks scheduled from follow-on schedule check
