[2022-06-27 07:07:00,998] {taskinstance.py:1043} INFO - Dependencies all met for <TaskInstance: first_airflow_dag.process_datetime scheduled__2022-06-27T07:06:00+00:00 [queued]>
[2022-06-27 07:07:01,011] {taskinstance.py:1043} INFO - Dependencies all met for <TaskInstance: first_airflow_dag.process_datetime scheduled__2022-06-27T07:06:00+00:00 [queued]>
[2022-06-27 07:07:01,011] {taskinstance.py:1249} INFO - 
--------------------------------------------------------------------------------
[2022-06-27 07:07:01,011] {taskinstance.py:1250} INFO - Starting attempt 1 of 1
[2022-06-27 07:07:01,011] {taskinstance.py:1251} INFO - 
--------------------------------------------------------------------------------
[2022-06-27 07:07:01,019] {taskinstance.py:1270} INFO - Executing <Task(PythonOperator): process_datetime> on 2022-06-27 07:06:00+00:00
[2022-06-27 07:07:01,024] {standard_task_runner.py:52} INFO - Started process 1007 to run task
[2022-06-27 07:07:01,027] {standard_task_runner.py:79} INFO - Running: ['***', 'tasks', 'run', 'first_***_dag', 'process_datetime', 'scheduled__2022-06-27T07:06:00+00:00', '--job-id', '62', '--raw', '--subdir', 'DAGS_FOLDER/second_demo.py', '--cfg-path', '/tmp/tmp4pb7xus5', '--error-file', '/tmp/tmpwmhf_5km']
[2022-06-27 07:07:01,027] {standard_task_runner.py:80} INFO - Job 62: Subtask process_datetime
[2022-06-27 07:07:01,067] {logging_mixin.py:109} INFO - Running <TaskInstance: first_***_dag.process_datetime scheduled__2022-06-27T07:06:00+00:00 [running]> on host f32f6d4577d5
[2022-06-27 07:07:01,109] {taskinstance.py:1448} INFO - Exporting the following env vars:
AIRFLOW_CTX_DAG_OWNER=***
AIRFLOW_CTX_DAG_ID=first_***_dag
AIRFLOW_CTX_TASK_ID=process_datetime
AIRFLOW_CTX_EXECUTION_DATE=2022-06-27T07:06:00+00:00
AIRFLOW_CTX_DAG_RUN_ID=scheduled__2022-06-27T07:06:00+00:00
[2022-06-27 07:07:01,115] {taskinstance.py:1774} ERROR - Task failed with exception
Traceback (most recent call last):
  File "/home/airflow/.local/lib/python3.7/site-packages/airflow/operators/python.py", line 174, in execute
    return_value = self.execute_callable()
  File "/home/airflow/.local/lib/python3.7/site-packages/airflow/operators/python.py", line 188, in execute_callable
    return self.python_callable(*self.op_args, **self.op_kwargs)
  File "/opt/airflow/dags/second_demo.py", line 17, in process_datetime
    'year': int(dt[-1]),
ValueError: invalid literal for int() with base 10: 'None'
[2022-06-27 07:07:01,123] {taskinstance.py:1288} INFO - Marking task as FAILED. dag_id=first_***_dag, task_id=process_datetime, execution_date=20220627T070600, start_date=20220627T070700, end_date=20220627T070701
[2022-06-27 07:07:01,131] {standard_task_runner.py:98} ERROR - Failed to execute job 62 for task process_datetime (invalid literal for int() with base 10: 'None'; 1007)
[2022-06-27 07:07:01,158] {local_task_job.py:154} INFO - Task exited with return code 1
[2022-06-27 07:07:01,177] {local_task_job.py:264} INFO - 0 downstream tasks scheduled from follow-on schedule check
